Workbook

Sheet How to use
A1: Planetary Analogue Catalogue: data entry workbook
A2: One row per site on the Sites tab; one row per source on the References tab.
A4: Progress
A5: Sites entered | B5: =COUNTA(Sites!B4:B503)
A6: Complete (ready to review) | B6: =COUNTIF(Sites!BB4:BB503,"Complete")
A7: Verified | B7: =COUNTIF(Sites!AX4:AX503,"Verified")
A8: References logged | B8: =COUNTA(References!A4:A503)
A10: How to fill it in
A11: White cells | B11: Type or pick a value. Columns marked * are required before an entry can be reviewed.
A12: Dropdown columns | B12: Click the cell and choose from the list. Lists live on the Vocabularies tab.
A13: "_other" and hazards columns | B13: Several values from the Vocabularies lists, separated by semicolons, e.g. "Moon; Europa".
A14: Grey columns (Checks) | B14: Calculated automatically. Do not type in them. "Complete" means every required field is filled and the site has at least one reference.
A15: Model entry | B15: Río Tinto (row 4 on Sites) is a good model of a complete entry.
A16: Unknown values | B16: Leave the cell blank. Never guess a number.
A17: Sources | B17: Add each paper to the References tab with the site id, and list which fields it supports.
A18: Ratings | B18: Use the Rating scales tab and fill rating_last_reviewed with the date you checked.
A19: Sensitive sites | B19: Set sensitive_site to Yes and coordinate_precision to "Approximately 10 km" or "Region only".
A20: Review status | B20: Draft while you work → In review when Complete → Verified after a second person checks it.
A22: Note | B22: All 16 sites were researched on 11 October 2026. Every value comes from a source on the References tab, apart from fields marked as judgement on the Research log tab. Hazard and access ratings are proposals: check them, then fill rating_last_reviewed and contributors. Open questions per site are on the Research log tab.
A24: Jump to
A25: =HYPERLINK("#'Site view'!B2","Site view: one site at a time")
A26: =HYPERLINK("#Sites!A2","Sites: Identity")
A27: =HYPERLINK("#Sites!M2","Sites: Analogue")
A28: =HYPERLINK("#Sites!T2","Sites: Geology")
A29: =HYPERLINK("#Sites!X2","Sites: Environment")
A30: =HYPERLINK("#Sites!AI2","Sites: Access")
A31: =HYPERLINK("#Sites!AQ2","Sites: Safety")
A32: =HYPERLINK("#Sites!AU2","Sites: Provenance")
A33: =HYPERLINK("#References!A2","References")
A35: Tip | B35: On the Sites tab, click the small minus buttons above the column letters to fold away sections you are not working on. id and name always stay visible on the left.

Sheet Site view
A1: Site view
A2: Choose a site: | B2: rio-tinto-es | C2: ← click, then use the dropdown
A3: Read-only view of one site. Make changes on the Sites tab (the Edit links jump to the right cell in Excel).
A4: Status | B4: =IFERROR(INDEX(Sites!$BB$4:$BB$503,MATCH($B$2,Sites!$A$4:$A$503,0))&": "&INDEX(Sites!$BA$4:$BA$503,MATCH($B$2,Sites!$A$4:$A$503,0))&" required fields missing, "&INDEX(Sites!$AZ$4:$AZ$503,MATCH($B$2,Sites!$A$4:$A$503,0))&" references","Site not found")
A6: Field | B6: Value | C6: Check | D6: Edit
A7: IDENTITY
A8: id * | B8: =IFERROR(IF(INDEX(Sites!$A$4:$A$503,MATCH($B$2,Sites!$A$4:$A$503,0))="","",INDEX(Sites!$A$4:$A$503,MATCH($B$2,Sites!$A$4:$A$503,0))),"") | C8: =IF(B8="","Required: missing","") | D8: =IFERROR(HYPERLINK("#Sites!A"&(MATCH($B$2,Sites!$A$4:$A$503,0)+3),"Edit"),"")
A9: name * | B9: =IFERROR(IF(INDEX(Sites!$B$4:$B$503,MATCH($B$2,Sites!$A$4:$A$503,0))="","",INDEX(Sites!$B$4:$B$503,MATCH($B$2,Sites!$A$4:$A$503,0))),"") | C9: =IF(B9="","Required: missing","") | D9: =IFERROR(HYPERLINK("#Sites!B"&(MATCH($B$2,Sites!$A$4:$A$503,0)+3),"Edit"),"")
A10: alt_names | B10: =IFERROR(IF(INDEX(Sites!$C$4:$C$503,MATCH($B$2,Sites!$A$4:$A$503,0))="","",INDEX(Sites!$C$4:$C$503,MATCH($B$2,Sites!$A$4:$A$503,0))),"") | C10: =IF(B10="","empty","") | D10: =IFERROR(HYPERLINK("#Sites!C"&(MATCH($B$2,Sites!$A$4:$A$503,0)+3),"Edit"),"")
A11: country * | B11: =IFERROR(IF(INDEX(Sites!$D$4:$D$503,MATCH($B$2,Sites!$A$4:$A$503,0))="","",INDEX(Sites!$D$4:$D$503,MATCH($B$2,Sites!$A$4:$A$503,0))),"") | C11: =IF(B11="","Required: missing","") | D11: =IFERROR(HYPERLINK("#Sites!D"&(MATCH($B$2,Sites!$A$4:$A$503,0)+3),"Edit"),"")
A12: country_code | B12: =IFERROR(IF(INDEX(Sites!$E$4:$E$503,MATCH($B$2,Sites!$A$4:$A$503,0))="","",INDEX(Sites!$E$4:$E$503,MATCH($B$2,Sites!$A$4:$A$503,0))),"") | C12: =IF(B12="","empty","") | D12: =IFERROR(HYPERLINK("#Sites!E"&(MATCH($B$2,Sites!$A$4:$A$503,0)+3),"Edit"),"")
A13: region | B13: =IFERROR(IF(INDEX(Sites!$F$4:$F$503,MATCH($B$2,Sites!$A$4:$A$503,0))="","",INDEX(Sites!$F$4:$F$503,MATCH($B$2,Sites!$A$4:$A$503,0))),"") | C13: =IF(B13="","empty","") | D13: =IFERROR(HYPERLINK("#Sites!F"&(MATCH($B$2,Sites!$A$4:$A$503,0)+3),"Edit"),"")
A14: latitude * | B14: =IFERROR(IF(INDEX(Sites!$G$4:$G$503,MATCH($B$2,Sites!$A$4:$A$503,0))="","",INDEX(Sites!$G$4:$G$503,MATCH($B$2,Sites!$A$4:$A$503,0))),"") | C14: =IF(B14="","Required: missing","") | D14: =IFERROR(HYPERLINK("#Sites!G"&(MATCH($B$2,Sites!$A$4:$A$503,0)+3),"Edit"),"")
A15: longitude * | B15: =IFERROR(IF(INDEX(Sites!$H$4:$H$503,MATCH($B$2,Sites!$A$4:$A$503,0))="","",INDEX(Sites!$H$4:$H$503,MATCH($B$2,Sites!$A$4:$A$503,0))),"") | C15: =IF(B15="","Required: missing","") | D15: =IFERROR(HYPERLINK("#Sites!H"&(MATCH($B$2,Sites!$A$4:$A$503,0)+3),"Edit"),"")
A16: coordinate_precision * | B16: =IFERROR(IF(INDEX(Sites!$I$4:$I$503,MATCH($B$2,Sites!$A$4:$A$503,0))="","",INDEX(Sites!$I$4:$I$503,MATCH($B$2,Sites!$A$4:$A$503,0))),"") | C16: =IF(B16="","Required: missing","") | D16: =IFERROR(HYPERLINK("#Sites!I"&(MATCH($B$2,Sites!$A$4:$A$503,0)+3),"Edit"),"")
A17: sensitive_site * | B17: =IFERROR(IF(INDEX(Sites!$J$4:$J$503,MATCH($B$2,Sites!$A$4:$A$503,0))="","",INDEX(Sites!$J$4:$J$503,MATCH($B$2,Sites!$A$4:$A$503,0))),"") | C17: =IF(B17="","Required: missing","") | D17: =IFERROR(HYPERLINK("#Sites!J"&(MATCH($B$2,Sites!$A$4:$A$503,0)+3),"Edit"),"")
A18: extent_km2 | B18: =IFERROR(IF(INDEX(Sites!$K$4:$K$503,MATCH($B$2,Sites!$A$4:$A$503,0))="","",INDEX(Sites!$K$4:$K$503,MATCH($B$2,Sites!$A$4:$A$503,0))),"") | C18: =IF(B18="","empty","") | D18: =IFERROR(HYPERLINK("#Sites!K"&(MATCH($B$2,Sites!$A$4:$A$503,0)+3),"Edit"),"")
A19: summary * | B19: =IFERROR(IF(INDEX(Sites!$L$4:$L$503,MATCH($B$2,Sites!$A$4:$A$503,0))="","",INDEX(Sites!$L$4:$L$503,MATCH($B$2,Sites!$A$4:$A$503,0))),"") | C19: =IF(B19="","Required: missing","") | D19: =IFERROR(HYPERLINK("#Sites!L"&(MATCH($B$2,Sites!$A$4:$A$503,0)+3),"Edit"),"")
A20: ANALOGUE
A21: analogue_for_primary * | B21: =IFERROR(IF(INDEX(Sites!$M$4:$M$503,MATCH($B$2,Sites!$A$4:$A$503,0))="","",INDEX(Sites!$M$4:$M$503,MATCH($B$2,Sites!$A$4:$A$503,0))),"") | C21: =IF(B21="","Required: missing","") | D21: =IFERROR(HYPERLINK("#Sites!M"&(MATCH($B$2,Sites!$A$4:$A$503,0)+3),"Edit"),"")
A22: analogue_for_other | B22: =IFERROR(IF(INDEX(Sites!$N$4:$N$503,MATCH($B$2,Sites!$A$4:$A$503,0))="","",INDEX(Sites!$N$4:$N$503,MATCH($B$2,Sites!$A$4:$A$503,0))),"") | C22: =IF(B22="","empty","") | D22: =IFERROR(HYPERLINK("#Sites!N"&(MATCH($B$2,Sites!$A$4:$A$503,0)+3),"Edit"),"")
A23: analogue_type_primary * | B23: =IFERROR(IF(INDEX(Sites!$O$4:$O$503,MATCH($B$2,Sites!$A$4:$A$503,0))="","",INDEX(Sites!$O$4:$O$503,MATCH($B$2,Sites!$A$4:$A$503,0))),"") | C23: =IF(B23="","Required: missing","") | D23: =IFERROR(HYPERLINK("#Sites!O"&(MATCH($B$2,Sites!$A$4:$A$503,0)+3),"Edit"),"")
A24: analogue_type_other | B24: =IFERROR(IF(INDEX(Sites!$P$4:$P$503,MATCH($B$2,Sites!$A$4:$A$503,0))="","",INDEX(Sites!$P$4:$P$503,MATCH($B$2,Sites!$A$4:$A$503,0))),"") | C24: =IF(B24="","empty","") | D24: =IFERROR(HYPERLINK("#Sites!P"&(MATCH($B$2,Sites!$A$4:$A$503,0)+3),"Edit"),"")
A25: target_feature | B25: =IFERROR(IF(INDEX(Sites!$Q$4:$Q$503,MATCH($B$2,Sites!$A$4:$A$503,0))="","",INDEX(Sites!$Q$4:$Q$503,MATCH($B$2,Sites!$A$4:$A$503,0))),"") | C25: =IF(B25="","empty","") | D25: =IFERROR(HYPERLINK("#Sites!Q"&(MATCH($B$2,Sites!$A$4:$A$503,0)+3),"Edit"),"")
A26: science_relevance * | B26: =IFERROR(IF(INDEX(Sites!$R$4:$R$503,MATCH($B$2,Sites!$A$4:$A$503,0))="","",INDEX(Sites!$R$4:$R$503,MATCH($B$2,Sites!$A$4:$A$503,0))),"") | C26: =IF(B26="","Required: missing","") | D26: =IFERROR(HYPERLINK("#Sites!R"&(MATCH($B$2,Sites!$A$4:$A$503,0)+3),"Edit"),"")
A27: analogue_limitations | B27: =IFERROR(IF(INDEX(Sites!$S$4:$S$503,MATCH($B$2,Sites!$A$4:$A$503,0))="","",INDEX(Sites!$S$4:$S$503,MATCH($B$2,Sites!$A$4:$A$503,0))),"") | C27: =IF(B27="","empty","") | D27: =IFERROR(HYPERLINK("#Sites!S"&(MATCH($B$2,Sites!$A$4:$A$503,0)+3),"Edit"),"")
A28: GEOLOGY
A29: geological_setting | B29: =IFERROR(IF(INDEX(Sites!$T$4:$T$503,MATCH($B$2,Sites!$A$4:$A$503,0))="","",INDEX(Sites!$T$4:$T$503,MATCH($B$2,Sites!$A$4:$A$503,0))),"") | C29: =IF(B29="","empty","") | D29: =IFERROR(HYPERLINK("#Sites!T"&(MATCH($B$2,Sites!$A$4:$A$503,0)+3),"Edit"),"")
A30: rock_types | B30: =IFERROR(IF(INDEX(Sites!$U$4:$U$503,MATCH($B$2,Sites!$A$4:$A$503,0))="","",INDEX(Sites!$U$4:$U$503,MATCH($B$2,Sites!$A$4:$A$503,0))),"") | C30: =IF(B30="","empty","") | D30: =IFERROR(HYPERLINK("#Sites!U"&(MATCH($B$2,Sites!$A$4:$A$503,0)+3),"Edit"),"")
A31: key_minerals | B31: =IFERROR(IF(INDEX(Sites!$V$4:$V$503,MATCH($B$2,Sites!$A$4:$A$503,0))="","",INDEX(Sites!$V$4:$V$503,MATCH($B$2,Sites!$A$4:$A$503,0))),"") | C31: =IF(B31="","empty","") | D31: =IFERROR(HYPERLINK("#Sites!V"&(MATCH($B$2,Sites!$A$4:$A$503,0)+3),"Edit"),"")
A32: age | B32: =IFERROR(IF(INDEX(Sites!$W$4:$W$503,MATCH($B$2,Sites!$A$4:$A$503,0))="","",INDEX(Sites!$W$4:$W$503,MATCH($B$2,Sites!$A$4:$A$503,0))),"") | C32: =IF(B32="","empty","") | D32: =IFERROR(HYPERLINK("#Sites!W"&(MATCH($B$2,Sites!$A$4:$A$503,0)+3),"Edit"),"")
A33: ENVIRONMENT
A34: environment_type_primary * | B34: =IFERROR(IF(INDEX(Sites!$X$4:$X$503,MATCH($B$2,Sites!$A$4:$A$503,0))="","",INDEX(Sites!$X$4:$X$503,MATCH($B$2,Sites!$A$4:$A$503,0))),"") | C34: =IF(B34="","Required: missing","") | D34: =IFERROR(HYPERLINK("#Sites!X"&(MATCH($B$2,Sites!$A$4:$A$503,0)+3),"Edit"),"")
A35: environment_type_other | B35: =IFERROR(IF(INDEX(Sites!$Y$4:$Y$503,MATCH($B$2,Sites!$A$4:$A$503,0))="","",INDEX(Sites!$Y$4:$Y$503,MATCH($B$2,Sites!$A$4:$A$503,0))),"") | C35: =IF(B35="","empty","") | D35: =IFERROR(HYPERLINK("#Sites!Y"&(MATCH($B$2,Sites!$A$4:$A$503,0)+3),"Edit"),"")
A36: ph_min | B36: =IFERROR(IF(INDEX(Sites!$Z$4:$Z$503,MATCH($B$2,Sites!$A$4:$A$503,0))="","",INDEX(Sites!$Z$4:$Z$503,MATCH($B$2,Sites!$A$4:$A$503,0))),"") | C36: =IF(B36="","empty","") | D36: =IFERROR(HYPERLINK("#Sites!Z"&(MATCH($B$2,Sites!$A$4:$A$503,0)+3),"Edit"),"")
A37: ph_max | B37: =IFERROR(IF(INDEX(Sites!$AA$4:$AA$503,MATCH($B$2,Sites!$A$4:$A$503,0))="","",INDEX(Sites!$AA$4:$AA$503,MATCH($B$2,Sites!$A$4:$A$503,0))),"") | C37: =IF(B37="","empty","") | D37: =IFERROR(HYPERLINK("#Sites!AA"&(MATCH($B$2,Sites!$A$4:$A$503,0)+3),"Edit"),"")
A38: temp_min_c | B38: =IFERROR(IF(INDEX(Sites!$AB$4:$AB$503,MATCH($B$2,Sites!$A$4:$A$503,0))="","",INDEX(Sites!$AB$4:$AB$503,MATCH($B$2,Sites!$A$4:$A$503,0))),"") | C38: =IF(B38="","empty","") | D38: =IFERROR(HYPERLINK("#Sites!AB"&(MATCH($B$2,Sites!$A$4:$A$503,0)+3),"Edit"),"")
A39: temp_max_c | B39: =IFERROR(IF(INDEX(Sites!$AC$4:$AC$503,MATCH($B$2,Sites!$A$4:$A$503,0))="","",INDEX(Sites!$AC$4:$AC$503,MATCH($B$2,Sites!$A$4:$A$503,0))),"") | C39: =IF(B39="","empty","") | D39: =IFERROR(HYPERLINK("#Sites!AC"&(MATCH($B$2,Sites!$A$4:$A$503,0)+3),"Edit"),"")
A40: salinity | B40: =IFERROR(IF(INDEX(Sites!$AD$4:$AD$503,MATCH($B$2,Sites!$A$4:$A$503,0))="","",INDEX(Sites!$AD$4:$AD$503,MATCH($B$2,Sites!$A$4:$A$503,0))),"") | C40: =IF(B40="","empty","") | D40: =IFERROR(HYPERLINK("#Sites!AD"&(MATCH($B$2,Sites!$A$4:$A$503,0)+3),"Edit"),"")
A41: altitude_min_m | B41: =IFERROR(IF(INDEX(Sites!$AE$4:$AE$503,MATCH($B$2,Sites!$A$4:$A$503,0))="","",INDEX(Sites!$AE$4:$AE$503,MATCH($B$2,Sites!$A$4:$A$503,0))),"") | C41: =IF(B41="","empty","") | D41: =IFERROR(HYPERLINK("#Sites!AE"&(MATCH($B$2,Sites!$A$4:$A$503,0)+3),"Edit"),"")
...

Sheet Sites
A1: IDENTITY | M1: ANALOGUE | T1: GEOLOGY | X1: ENVIRONMENT | AI1: ACCESS | AQ1: SAFETY | AU1: PROVENANCE | AZ1: CHECKS (AUTOMATIC)
A2: id * | B2: name * | C2: alt_names | D2: country * | E2: country_code | F2: region | G2: latitude * | H2: longitude * | I2: coordinate_precision * | J2: sensitive_site * | K2: extent_km2 | L2: summary * | M2: analogue_for_primary * | N2: analogue_for_other | O2: analogue_type_primary * | P2: analogue_type_other | Q2: target_feature | R2: science_relevance * | S2: analogue_limitations | T2: geological_setting | U2: rock_types | V2: key_minerals | W2: age | X2: environment_type_primary * | Y2: environment_type_other | Z2: ph_min | AA2: ph_max | AB2: temp_min_c | AC2: temp_max_c | AD2: salinity | AE2: altitude_min_m | AF2: altitude_max_m | AG2: biology_present | AH2: notable_organisms | AI2: access_level * | AJ2: permits_required * | AK2: permit_authority | AL2: land_status | AM2: nearest_town | AN2: best_season | AO2: transport_notes | AP2: sampling_rules | AQ2: hazard_rating * | AR2: hazards * | AS2: safety_notes | AT2: rating_last_reviewed * | AU2: contributors * | AV2: date_added * | AW2: last_verified | AX2: review_status * | AY2: notes_for_reviewer | AZ2: reference_count | BA2: required_missing | BB2: entry_check
A3: Short unique slug: site-name-countrycode | B3: Common name of the site | C3: Other names; separate with ; | D3: Country or "International waters" | E3: ISO 3166 two-letter code | F3: State, province or area | G3: Decimal degrees, WGS84 (south is minus) | H3: Decimal degrees, WGS84 (west is minus) | I3: How precisely to publish the location | J3: Fragile, protected or Indigenous land? | K3: Approximate area in km² | L3: One line, under 300 characters | M3: Main body it is an analogue for | N3: Other bodies; separate with ; | O3: Main kind of analogue | P3: Other kinds; separate with ; | Q3: Planetary feature it is compared with | R3: Why it is a good analogue | S3: Where the comparison breaks down | T3: Main setting | U3: Separate with ; | V3: mindat.org names; separate with ; | W3: Age of rocks or features | X3: Main environment | Y3: Others; separate with ; | Z3: pH, 0 to 14 | AA3: pH, 0 to 14 | AB3: Temperature, °C | AC3: Temperature, °C | AD3: Value with units, or a description | AE3: Metres above sea level | AF3: Metres above sea level | AG3: Is life present at the site? | AH3: Key organisms or communities | AI3: 1 to 5; see Rating scales tab | AJ3: Are permits needed? | AK3: Who issues them; add a link | AL3: Who owns or manages the land | AN3: When to visit | AO3: Roads, 4x4, boat, hike | AP3: What may be sampled, under which permit | AQ3: 1 to 5; see Rating scales tab | AR3: From the hazards list; separate with ; | AS3: Precautions visitors should take | AT3: Date ratings were checked (YYYY-MM-DD) | AU3: Names or ORCIDs; separate with ; | AV3: YYYY-MM-DD | AW3: YYYY-MM-DD | AX3: Where the entry is in review | AY3: Anything still to check | AZ3: Rows for this id on the References tab | BA3: Required fields still empty | BB3: Complete = all required fields + 1 reference
A4: rio-tinto-es | B4: Río Tinto | C4: Rio Tinto; Tinto River | D4: Spain | E4: ES | F4: Huelva, Andalusia | G4: 37.21 | H4: -6.938 | I4: Approximately 10 km | J4: No | K4: 169.57 | L4: Highly acidic, iron-rich river (mean pH 2.3) rising at Peña de Hierro in the Iberian Pyrite Belt and reaching the Atlantic at Huelva. Its ferric sulphates and iron oxides, including jarosite and hematite, make it a classic analogue for Meridiani Planum, Mars. | M4: Mars | N4: Europa | O4: Mineralogical | P4: Geochemical; Habitability / biological | Q4: Meridiani Planum sulphate- and hematite-bearing outcrops (jarosite, hematite) | R4: Río Tinto precipitates jarosite, schwertmannite, goethite and hematite from acidic, iron-rich water, comparable to the jarosite and hematite identified at Meridiani Planum by Mössbauer spectroscopy. Its acidity is generated by chemolithotrophic micro-organisms oxidising subsurface pyrite, making it a model for iron- and sulphur-based habitability on Mars. | S4: Meridiani sediments formed in an arid aeolian and aqueous setting, whereas Tinto sediments form in seasonally arid stream beds; Tinto acidity comes from pyrite oxidation, which is not the only possible source of acidic fluids on Mars; ferric sulphates do not persist in the Tinto rock record, unlike Meridiani; the basin has more than 5,000 years of mining history. | T4: Hydrothermal / ore deposit | U4: Massive sulphide (pyrite) ore bodies; gossans; ferruginous river terraces | V4: Jarosite; Hydroniumjarosite; Schwertmannite; Copiapite; Coquimbite; Gypsum; Goethite; Hematite; Pyrite; Siderite | W4: Iberian Pyrite Belt formed during the Hercynian orogeny; gossans older than 6 Ma; oldest river terrace dated to 2.1 Ma | X4: Acidic | Y4: Iron-rich; Sulphur-rich | Z4: 2 | AA4: 2.5 | AG4: Yes | AH4: Acidithiobacillus; Leptospirillum; Acidiphilium; Chlamydomonas; Dunaliella; Chlorella; Klebsormidium; Cyanidium; Euglena; pennate diatoms; Methanosaeta concilii (sediments) | AI4: 2 | AJ4: Varies | AK4: Junta de Andalucía (Consejería de Medio Ambiente), managing authority of the Paisaje Protegido de Río Tinto | AL4: Protected area / national park | AM4: Minas de Riotinto; Nerva | AP4: Protected landscape (Decree 558/2004): access to publicly owned land only via designated, signposted places; the environment authority may restrict zones for research or conservation; aggregate extraction and actions altering the river's water character are prohibited; no specific sampling rules are set out in the decree. | AQ4: 2 | AR4: Acidic or caustic water; Old mine workings | AS4: River water is around pH 2; avoid skin and eye contact and use gloves and eye protection when sampling. The basin contains extensive historical and active mine workings (copper production restarted in 2016). | AV4: 46306 | AX4: Draft | AY4: Ratings are PROPOSALS by Claude: check against Rating scales, then fill rating_last_reviewed. Open issues: see Research log tab. | AZ4: =IF($B4="","",COUNTIF(References!$A$4:$A$503,$A4)) | BA4: =IF($B4="","",(LEN(A4)=0)+(LEN(B4)=0)+(LEN(D4)=0)+(LEN(G4)=0)+(LEN(H4)=0)+(LEN(I4)=0)+(LEN(J4)=0)+(LEN(L4)=0)+(LEN(M4)=0)+(LEN(O4)=0)+(LEN(R4)=0)+(LEN(X4)=0)+(LEN(AI4)=0)+(LEN(AJ4)=0)+(LEN(AQ4)=0)+(LEN(AR4)=0)+(LEN(AT4)=0)+(LEN(AU4)=0)+(LEN(AV4)=0)+(LEN(AX4)=0)) | BB4: =IF($B4="","",IF(AND(BA4=0,AZ4>=1),"Complete","Incomplete"))
A5: atacama-yungay-cl | B5: Atacama Desert – Yungay area | C5: Yungay hyperarid site | D5: Chile | E5: CL | F5: Antofagasta Region, hyperarid core of the Atacama Desert | G5: -24.1 | H5: -70.01 | I5: Approximately 10 km | J5: No | L5: Hyperarid core of the Atacama Desert near Yungay, Chile. Its saline soils, rich in nitrates, sulphates and perchlorates and very poor in organics, hold extremely sparse microbial life. The site is a classic Mars soil analogue first proposed in 2003. | M5: Mars | O5: Habitability / biological | P5: Geochemical | Q5: Hyperarid, oxidising, nitrate- and perchlorate-bearing soils with trace organics (dry limit of microbial life) | R5: Navarro-González et al. (2003) found Mars-like soils at Yungay: trace organics, very few culturable bacteria, no recoverable DNA, and non-biological decomposition of organics in Viking-style labelled-release experiments. Later work uses the site as an analogue for an incomplete nitrogen cycle on Mars and for the effect of rare floods on dry-adapted ecosystems. | V5: Halite; Nitratine | X5: Hyperarid | Y5: Evaporite | AD5: Highly saline soils enriched in nitrates, sulphates and perchlorates; halite and sodium nitrate identified by XRD in post-rain lagoons | AG5: Yes | AH5: Halomonas yungayensis (new species described from post-2017-rain lagoons); Halomonas, Marinimicrobium, Marinobacter, Acinetobacter dominate post-rain soils | AI5: 2 | AQ5: 2 | AV5: 46306 | AX5: Draft | AY5: Ratings are PROPOSALS by Claude: check against Rating scales, then fill rating_last_reviewed. Open issues: see Research log tab. | AZ5: =IF($B5="","",COUNTIF(References!$A$4:$A$503,$A5)) | BA5: =IF($B5="","",(LEN(A5)=0)+(LEN(B5)=0)+(LEN(D5)=0)+(LEN(G5)=0)+(LEN(H5)=0)+(LEN(I5)=0)+(LEN(J5)=0)+(LEN(L5)=0)+(LEN(M5)=0)+(LEN(O5)=0)+(LEN(R5)=0)+(LEN(X5)=0)+(LEN(AI5)=0)+(LEN(AJ5)=0)+(LEN(AQ5)=0)+(LEN(AR5)=0)+(LEN(AT5)=0)+(LEN(AU5)=0)+(LEN(AV5)=0)+(LEN(AX5)=0)) | BB5: =IF($B5="","",IF(AND(BA5=0,AZ5>=1),"Complete","Incomplete"))
A6: dallol-et | B6: Dallol | C6: Dallol dome; Dallol hydrothermal system | D6: Ethiopia | E6: ET | F6: Danakil Depression, Afar Region | G6: 14.242 | H6: 40.3 | I6: Approximately 1 km | J6: No | L6: Protovolcanic dome in the Danakil Depression, Ethiopia, where basaltic magma heats evaporites. The result is anoxic, hypersaline, iron-rich brines (pH down to -1.7, up to about 108 °C). The site is used to study the limits of life and iron mineralogy relevant to Mars. | M6: Mars | N6: Early Earth | O6: Geochemical | P6: Habitability / biological; Mineralogical | Q6: Hyperacidic, hypersaline, iron-rich hydrothermal springs and brine pools precipitating jarosite-group minerals, akaganeite and hematite over halite | R6: Kotopoulou et al. (2019) describe Dallol as a Martian analogue where inorganic iron oxidation precipitates jarosite and akaganeite, minerals also identified on Mars. Belilla et al. (2019) found two physicochemical barriers to life where liquid water is present: chaotropic Mg/Ca brines, and pH around 0 combined with NaCl saturation. Diverse ultrasmall archaea occur only outside these conditions. | T6: Volcanic | U6: Evaporites (halite-dominated salt deposits, potash) over basaltic magma | V6: Halite; Jarosite; Akaganeite; Hematite; Gypsum; Sylvite; Carnallite; Sulphur; Goethite; Anhydrite | W6: Dallol volcano formed in phreatic eruptions in 1926. The last activity, possibly degassing, was in January 2011. The age of the hydrothermal system is unknown. | X6: Hot spring / hydrothermal | Y6: Acidic; Hypersaline; Iron-rich; Evaporite | Z6: -1.7 | AA6: 2.5 | AB6: 32 | AC6: 108.4 | AD6: Hypersaline: brines supersaturated in NaCl, with up to 150 g/L iron (mean about 22.5 g/L in spring brines). Mg/Ca-dominated chaotropic brines also occur. | AE6: -120 | AF6: -60 | AG6: Yes | AH6: Highly diverse ultrasmall archaea (including Nanohaloarchaea) in the surrounding salt plains and less extreme brines. No life was detected in the hyperacidic, hypersaline dome ponds. | AI6: 4 | AL6: Unknown | AQ6: 4 | AR6: Extreme heat; Toxic gas; Acidic or caustic water; Political instability | AS6: The UK FCDO (updated 7 October 2026) advises against all but essential travel to Afar, and against all travel within 20 km of the Eritrean border and within 50 km of Tigray. It reports renewed clashes in parts of Afar. Foreign nationals currently cannot fly into Afar airports, and medical facilities outside Addis Ababa are extremely limited. Fumaroles emit CO2, H2S and SO2. Brines reach about 108 °C and pH below 0. | AV6: 46306 | AX6: Draft | AY6: Ratings are PROPOSALS by Claude: check against Rating scales, then fill rating_last_reviewed. geological_setting also: Evaporite basin; Hydrothermal / ore deposit Open issues: see Research log tab. | AZ6: =IF($B6="","",COUNTIF(References!$A$4:$A$503,$A6)) | BA6: =IF($B6="","",(LEN(A6)=0)+(LEN(B6)=0)+(LEN(D6)=0)+(LEN(G6)=0)+(LEN(H6)=0)+(LEN(I6)=0)+(LEN(J6)=0)+(LEN(L6)=0)+(LEN(M6)=0)+(LEN(O6)=0)+(LEN(R6)=0)+(LEN(X6)=0)+(LEN(AI6)=0)+(LEN(AJ6)=0)+(LEN(AQ6)=0)+(LEN(AR6)=0)+(LEN(AT6)=0)+(LEN(AU6)=0)+(LEN(AV6)=0)+(LEN(AX6)=0)) | BB6: =IF($B6="","",IF(AND(BA6=0,AZ6>=1),"Complete","Incomplete"))
A7: mcmurdo-dry-valleys-aq | B7: McMurdo Dry Valleys | C7: Dry Valleys; McMurdo Dry Valleys ASMA No. 2 | D7: Antarctica | E7: AQ | F7: Victoria Land, East Antarctica (between the East Antarctic Ice Sheet and McMurdo Sound/Ross Sea) | G7: -77 | H7: 162 | I7: Region only | J7: Yes | K7: 4500 | L7: About 4,500 km2 of mostly ice-free valleys in Victoria Land: a cold, extremely arid, windy polar desert of valleys, ice-covered lakes and permafrost soils. A long-standing Mars analogue (used by NASA since Viking) and home of cryptoendolithic microbial communities living inside rocks. | M7: Mars | N7: Early Earth | O7: Habitability / biological | P7: Geological / geomorphological; Cryospheric | Q7: Cryptoendolithic communities in porous rocks; cold-desert soils, permafrost and ice-covered lakes | R7: The cold, extremely arid and windy climate is regarded as an analogue for contemporary Mars and ancient Earth. Cryptoendolithic lichens and microbes survive by growing between the crystals of porous rocks, a model for where life might persist near the surface of Mars. Microclimate zonation and geomorphic processes are used to interpret Martian landforms and climate change. | S7: Unlike Mars, the valleys have an oxygen-rich atmosphere, liquid water in summer (meltwater streams and lakes) and annual precipitation of around 100 mm; endolithic life is therefore not directly comparable with present-day Martian conditions. | T7: Glacial | U7: Granite; gneiss; marble and calc-schist (Asgard Formation, Skelton Group); granitoid plutons and dykes (Granite Harbour Intrusives); Beacon Supergroup sedimentary rocks; Ferrar Dolerite; McMurdo Volcanic Group basalt; glacial till | W7: Basement metamorphic and intrusive rocks overlain by the Beacon Supergroup intruded by Jurassic Ferrar Dolerite; McMurdo Volcanic Group basalts 2.1–4.4 Ma | X7: Polar desert | Y7: Permafrost; Hypersaline | AB7: -65.7 | AC7: 12 | AD7: Mostly fresh to saline ice-covered lakes; Lake Vida saline; Don Juan Pond the most saline water body | AG7: Yes | AH7: Cryptoendolithic lichens and photosynthetic bacteria inside porous rocks; microbial mats; cryoconite communities; anaerobic iron- and sulphur-based bacteria beneath Taylor Glacier | AI7: 5 | AJ7: Yes | AK7: Competent national authority of the expedition's Antarctic Treaty Party (e.g. UK: FCDO Polar Regions Department), under the Protocol on Environmental Protection; separate permits to enter ASPAs 123, 131, 138 and 154 inside the ASMA | AL7: Protected area / national park | AM7: Ross Island (helicopter departure point) | AO7: Access normally by helicopter from Ross Island, or over sea ice via New Harbor or Marble Point. Helicopters should use designated pads; overflight restrictions over ASPAs 123, 131 and 154. Vehicles restricted to lake ice or existing tracks unless specifically authorised. | AP7: Specimens (including rocks and fossils) only for scientific or associated educational purposes; collect only the minimum endolithic community sample needed for analysis; taking of native flora/fauna needs an Annex II permit; avoid trampling microbial mats (e.g. walk only on rocks at Boulder Pavement); follow ASMA zoning (Facilities, Tourism zone near Canada Glacier, Special Features). | AQ7: 4 | AR7: Extreme cold; Remoteness / no phone signal | AS7: Strong katabatic winds: secure all equipment and supplies. Take extreme care with vehicles on lake ice to avoid rollover or breaking through. Spill kits and secondary containment required for fuel and chemicals. Record air temperatures range from 12.0 °C to −65.7 °C. | AV7: 46306 | AX7: Draft | AY7: Ratings are PROPOSALS by Claude: check against Rating scales, then fill rating_last_reviewed. Open issues: see Research log tab. | AZ7: =IF($B7="","",COUNTIF(References!$A$4:$A$503,$A7)) | BA7: =IF($B7="","",(LEN(A7)=0)+(LEN(B7)=0)+(LEN(D7)=0)+(LEN(G7)=0)+(LEN(H7)=0)+(LEN(I7)=0)+(LEN(J7)=0)+(LEN(L7)=0)+(LEN(M7)=0)+(LEN(O7)=0)+(LEN(R7)=0)+(LEN(X7)=0)+(LEN(AI7)=0)+(LEN(AJ7)=0)+(LEN(AQ7)=0)+(LEN(AR7)=0)+(LEN(AT7)=0)+(LEN(AU7)=0)+(LEN(AV7)=0)+(LEN(AX7)=0)) | BB7: =IF($B7="","",IF(AND(BA7=0,AZ7>=1),"Complete","Incomplete"))
A8: haughton-crater-ca | B8: Haughton impact structure | C8: Haughton crater; Haughton Dome | D8: Canada | E8: CA | F8: Devon Island, Nunavut | G8: 75.383 | H8: -89.667 | I8: Approximately 10 km | J8: Yes | L8: Well-preserved c. 23 km impact structure on Devon Island in the Canadian High Arctic polar desert. It is home to the Haughton-Mars Project research station and is used for Mars and Moon geology, astrobiology and exploration analogue work. | M8: Mars | N8: Moon | O8: Impact | P8: Geological / geomorphological; Habitability / biological; Operational (instrument, rover or crew testing) | Q8: Crater-fill impact melt breccias; post-impact hydrothermal deposits; glacial and periglacial landforms and canyons (e.g. Astronaut Canyon, compared with a tributary of Ius Chasma on Mars) | R8: One of the best-preserved impact structures on Earth, in a cold, dry polar desert where weathering is slow. Heat from the impact melts drove a hydrothermal system that may have been a warm, wet microbial habitat, which makes it a model for impact-generated habitats on Mars. The site is also used to test habitats, spacesuits, rovers and drones for Moon and Mars missions. | T8: Impact | U8: Impact melt breccia; shale; siltstone; gneiss (basement); lacustrine mudstone and siltstone (Haughton Formation) | V8: Calcite; Anhydrite | W8: Impact c. 31 Ma (40Ar/39Ar weighted mean 31.04 ± 0.37 Ma; U-Pb lower intercept 31.8 ± 1.7 Ma; Erickson et al. 2021). An earlier estimate of c. 39 Ma (Osinski et al. 2005) is now superseded. Haughton Formation lake sediments are Miocene. | X8: Impact structure | Y8: Polar desert; Permafrost | AG8: Yes | AI8: 4 | AJ8: Yes | AK8: Nunavut Research Institute (Scientific Research Licence); Qikiqtani Inuit Association (Access to Inuit Owned Lands Permit); Nunavut Impact Review Board (screening of land-based research); Crown-Indigenous Relations and Northern Affairs Canada (Territorial Land Use Permit on Crown land); Mars Institute (written permission for non-Nunavut visitors to the HMP leased land) | AL8: Indigenous or community land | AN8: Summer (HMP field campaigns have run every summer since 1997) | AO8: No road access. The HMP Research Station has a c. 200 m dirt airstrip, and ATVs are used locally. The Mars Institute asks visitors to contact it first to confirm the airstrip is clear, find out where experiments are running and learn the ATV trail routes. | AP8: A NRI Scientific Research Licence is needed for natural and physical science. Land-based research is screened by the NIRB. Archaeological and palaeontological sites need permits from GN Culture and Heritage. Access to Inuit Owned Land needs a permit from the designated Inuit organisation. | AQ8: 4 | AR8: Extreme cold; Dangerous wildlife; Remoteness / no phone signal | AS8: Polar bears do reach field camps on Devon Island. Western University teams use electrified bear fencing around sleeping tents, set about a football field's distance from food, lab and toilet tents. They ban food and scented products from sleeping tents and carry shotguns and bear bangers. Report polar bear sightings to the local Government of Nunavut wildlife office. | AV8: 46306 | AX8: Draft | AY8: Ratings are PROPOSALS by Claude: check against Rating scales, then fill rating_last_reviewed. land_status also: Research station Open issues: see Research log tab. | AZ8: =IF($B8="","",COUNTIF(References!$A$4:$A$503,$A8)) | BA8: =IF($B8="","",(LEN(A8)=0)+(LEN(B8)=0)+(LEN(D8)=0)+(LEN(G8)=0)+(LEN(H8)=0)+(LEN(I8)=0)+(LEN(J8)=0)+(LEN(L8)=0)+(LEN(M8)=0)+(LEN(O8)=0)+(LEN(R8)=0)+(LEN(X8)=0)+(LEN(AI8)=0)+(LEN(AJ8)=0)+(LEN(AQ8)=0)+(LEN(AR8)=0)+(LEN(AT8)=0)+(LEN(AU8)=0)+(LEN(AV8)=0)+(LEN(AX8)=0)) | BB8: =IF($B8="","",IF(AND(BA8=0,AZ8>=1),"Complete","Incomplete"))
A9: iceland-volcanic-fields-is | B9: Iceland volcanic fields (Holuhraun and Krafla) | C9: Holuhraun lava field; Krafla caldera | D9: Iceland | E9: IS | F9: North-east Iceland: Highlands north of Vatnajökull (Holuhraun) and Mývatn area (Krafla) | G9: 64.85 | H9: -16.83 | I9: Region only | J9: No | K9: 85 | L9: Young basaltic fissure-fed lava fields in Iceland's rift zone: the 2014–15 Holuhraun flow-field north of Vatnajökull and the Krafla caldera near Mývatn. They are used as analogues for young Martian volcanic terrains and for aqueous alteration of basalt. | M9: Mars | O9: Volcanic | P9: Geological / geomorphological; Mineralogical | Q9: The 2014–15 Holuhraun fissure-fed lava flow-field ('transitional' lavas, polygonal terrain, lava–water interaction); altered Icelandic basalts with smectite clays and other hydrous silicates; the Krafla caldera (c. 10 km) and its 90 km fissure zone | R9: Holuhraun is a large-volume, fissure-fed eruption used as an analogue for Elysium Planitia, the youngest volcanic terrain on Mars. Lava morphologies and fissure systems there point to similar extensional settings. Water-altered Icelandic basalts are used to test how well spectroscopic and XRD methods detect clay minerals, to help interpret Noachian aqueous environments on Mars. | T9: Volcanic | U9: Basalt; rhyolite (magma found at c. 2.1 km depth at Krafla) | W9: Holuhraun lava erupted 29 August 2014 – 27 February 2015; Krafla Fires eruptions 1975–1984 | X9: Lava field / lava tube | Y9: Hot spring / hydrothermal | AI9: 3 | AK9: Nature Conservation Agency of Iceland (Vatnajökull National Park) | AL9: Protected area / national park | AN9: Summer. Highland roads usually open between late May and mid-July, depending on snow. | AO9: Holuhraun is in the Askja & Herðubreiðarlindir area of Vatnajökull National Park and is reached by seasonal highland roads. Roads in conservation areas may stay closed until the area can take visitors even when the road is clear. Check road.is or call 1777 for current conditions. Krafla is in the Mývatn area of north Iceland. | AP9: Visitors may only go on the waymarked trail from the Holuhraun parking lot, and the thin lava crust is easily damaged. The park lists permits but the page gives no details, so ask the park office about research sampling. | AQ9: 3 | AR9: Unstable ground; Volcanic activity | AS9: The Holuhraun lava is extremely rugged and difficult terrain, with a thin, fragile crust, so keep to the marked trail. Holuhraun was fed from the Bárðarbunga system, about 41 km to the south-west. | AV9: 46306 | AX9: Draft | AY9: Ratings are PROPOSALS by Claude: check against Rating scales, then fill rating_last_reviewed. geological_setting also: Hydrothermal / ore deposit Open issues: see Research log tab. | AZ9: =IF($B9="","",COUNTIF(References!$A$4:$A$503,$A9)) | BA9: =IF($B9="","",(LEN(A9)=0)+(LEN(B9)=0)+(LEN(D9)=0)+(LEN(G9)=0)+(LEN(H9)=0)+(LEN(I9)=0)+(LEN(J9)=0)+(LEN(L9)=0)+(LEN(M9)=0)+(LEN(O9)=0)+(LEN(R9)=0)+(LEN(X9)=0)+(LEN(AI9)=0)+(LEN(AJ9)=0)+(LEN(AQ9)=0)+(LEN(AR9)=0)+(LEN(AT9)=0)+(LEN(AU9)=0)+(LEN(AV9)=0)+(LEN(AX9)=0)) | BB9: =IF($B9="","",IF(AND(BA9=0,AZ9>=1),"Complete","Incomplete"))
A10: pilbara-strelley-pool-au | B10: Pilbara Craton: Strelley Pool and Dresser formations | C10: Strelley Pool Chert; Trendall locality; North Pole Dome; Dresser Mine | D10: Australia | E10: AU | F10: Pilbara, Western Australia (East Pilbara Shire) | G10: -21.207 | H10: 119.308 | I10: Approximately 10 km | J10: Yes | L10: Paleoarchean rocks of the Pilbara Craton holding some of Earth's oldest stromatolites (Strelley Pool, c. 3.43 Ga) and c. 3.48 Ga hot-spring deposits (Dresser Formation). A key early-Earth and Mars biosignature analogue linked to Jezero crater studies. | M10: Early Earth | N10: Mars | O10: Habitability / biological | P10: Geological / geomorphological; Mineralogical; Geochemical | Q10: c. 3.43 Ga stromatolites of the Strelley Pool Chert (seven morphotypes on a peritidal carbonate platform); c. 3.48 Ga geyserite and hot-spring sinter of the Dresser Formation | R10: Strelley Pool stromatolites are among the strongest evidence for life c. 3.43 Ga, and their morphology and environmental context are used to argue for biogenicity. Dresser Formation geyserite with stromatolites and palisade fabric suggests life in terrestrial hot springs c. 3.48 Ga, which the authors present as an analogue for seeking fossil life in ancient Martian hot springs. The Mount Ada Basalt and Strelley Pool rocks have been compared with the olivine-carbonate unit at Jezero crater. | S10: Rocks have been silicified, metamorphosed and deformed over >3 billion years; biogenicity of some structures (e.g. small conical forms) is disputed; Earth's Archean surface chemistry and plate-tectonic setting differ from Mars. | T10: Ancient craton | U10: Chert; stromatolitic carbonate (dolomite); sandstone; conglomerate; breccia; geyserite (siliceous sinter); basalt; komatiitic basalt; felsic tuff | V10: Quartz; Dolomite; Calcite; Baryte; Pyrite; Galena; Hematite; Kaolinite; Illite; Anatase; Ankerite; Siderite | W10: Strelley Pool Chert c. 3.43 Ga (Paleoarchean); Dresser Formation c. 3.48 Ga | X10: Hot spring / hydrothermal | Y10: Hypersaline | AG10: Yes | AH10: Fossil microbial communities only (stromatolites, microbial mat fabrics, inferred EPS with gas bubbles); no living analogue biota studied | AI10: 3 | AJ10: Yes | AK10: Geological Survey of Western Australia (fieldwork permits cited by Duda et al. 2016); native title and pastoral-lease holders may also need to be consulted (unconfirmed) | AL10: Unknown | AM10: Marble Bar (Strelley Pool is c. 34 km W on Six Mile Creek) | AN10: Cooler months, June to August (mean daily maximum c. 27 °C at Marble Bar); avoid December–January (often >45 °C) and the December–March wet/cyclone season | AO10: Remote: Marble Bar is 152 km SE of Port Hedland, and Strelley Pool is c. 34 km W of Marble Bar. Road conditions and 4WD needs not confirmed from an official source. | AP10: Fieldwork has required permits from the Geological Survey of Western Australia; Duda et al. (2016) inspected the Trendall locality outcrop without sampling it. Strelley Pool is classified by the National Trust and listed as an indicative place on the Register of the National Estate. | AQ10: 3 | AR10: Extreme heat; Remoteness / no phone signal; Flash flood | AS10: Marble Bar holds the world record of 160 consecutive days at or above 37.8 °C, with a record high of 49.3 °C; cyclones can bring very heavy rain. Plan for heat, water and remote travel. | AV10: 46306 | AX10: Draft | AY10: Ratings are PROPOSALS by Claude: check against Rating scales, then fill rating_last_reviewed. geological_setting also: Hydrothermal / ore deposit Open issues: see Research log tab. | AZ10: =IF($B10="","",COUNTIF(References!$A$4:$A$503,$A10)) | BA10: =IF($B10="","",(LEN(A10)=0)+(LEN(B10)=0)+(LEN(D10)=0)+(LEN(G10)=0)+(LEN(H10)=0)+(LEN(I10)=0)+(LEN(J10)=0)+(LEN(L10)=0)+(LEN(M10)=0)+(LEN(O10)=0)+(LEN(R10)=0)+(LEN(X10)=0)+(LEN(AI10)=0)+(LEN(AJ10)=0)+(LEN(AQ10)=0)+(LEN(AR10)=0)+(LEN(AT10)=0)+(LEN(AU10)=0)+(LEN(AV10)=0)+(LEN(AX10)=0)) | BB10: =IF($B10="","",IF(AND(BA10=0,AZ10>=1),"Complete","Incomplete"))
A11: shark-bay-hamelin-pool-au | B11: Hamelin Pool Marine Nature Reserve, Shark Bay | C11: Hamelin Pool; Shark Bay stromatolites | D11: Australia | E11: AU | F11: Gascoyne, Western Australia (Shark Bay World Heritage Area) | G11: -26.44 | H11: 114.35 | I11: Region only | J11: Yes | K11: 1270 | L11: Hypersaline marine reserve in the Shark Bay World Heritage Area with the world's most diverse and abundant living marine stromatolites and microbial mats. A modern model for early-Earth microbial ecosystems and biosignatures. | M11: Early Earth | N11: Mars | O11: Habitability / biological | P11: Geochemical | Q11: Living marine stromatolites, microbialites and microbial mats (pustular, smooth and colloform mat types) | R11: Hamelin Pool's living stromatolites are modern counterparts of stromatolites found in the fossil record back to the Archean, so they serve as model systems for carbon cycling and microbial mat ecosystems. Metagenomics shows mats dominated by Proteobacteria and Cyanobacteria, with sulphate reducers and methanogens. | S11: Modern biota and an oxygenated atmosphere differ from Archean conditions; the sources opened do not discuss Mars directly, so the Mars link is indirect (via ancient stromatolite biosignatures). | T11: Sedimentary basin | U11: Microbial carbonate (stromatolites, microbialites); coquina (cockle-shell limestone) | X11: Hypersaline | AB11: 11 | AC11: 33 | AD11: About twice normal seawater; 54.5–56 ppt at Spaven Province sampling sites (April 2014), with 66–88 ppt reported across the pool | AG11: Yes | AH11: Cyanobacteria (Entophysalis, Dichothrix, Scytonema); Proteobacteria; Desulfovibrionales (sulphate reducers); methanogenic Euryarchaeota (Methanobacteriales); Thaumarchaeota | AI11: 2 | AJ11: Yes | AK11: Department of Biodiversity, Conservation and Attractions (DBCA), Western Australia (conditional licence for scientific access); Australian Government environment department for sample export/collection (cited in Babilonia et al. 2018) | AL11: Protected area / national park | AM11: Denham (c. 100 km NW); Overlander Roadhouse c. 35 km | AO11: 27 km from the North West Coastal Highway via Shark Bay Road; sealed except a short 2WD-suitable unsealed section to the car park. 750 m return walk from the car park to the stromatolites. | AP11: Scientific access requires a conditional licence from DBCA. Walking below the high-water mark is not permitted; no swimming, snorkelling, diving or boating over stromatolites or within 300 m of shore; no fishing. Stay on the boardwalk/viewing area. Boardwalk closed since Cyclone Seroja damage; view from the temporary fence. | AQ11: 2 | AR11: Remoteness / no phone signal | AS11: DBCA advises planning your visit and carrying a personal locator beacon (PLB). Drones must follow CASA rules; never enter the water to retrieve one. | AV11: 46306 | AX11: Draft | AY11: Ratings are PROPOSALS by Claude: check against Rating scales, then fill rating_last_reviewed. land_status also: UNESCO site; Indigenous or community land Open issues: see Research log tab. | AZ11: =IF($B11="","",COUNTIF(References!$A$4:$A$503,$A11)) | BA11: =IF($B11="","",(LEN(A11)=0)+(LEN(B11)=0)+(LEN(D11)=0)+(LEN(G11)=0)+(LEN(H11)=0)+(LEN(I11)=0)+(LEN(J11)=0)+(LEN(L11)=0)+(LEN(M11)=0)+(LEN(O11)=0)+(LEN(R11)=0)+(LEN(X11)=0)+(LEN(AI11)=0)+(LEN(AJ11)=0)+(LEN(AQ11)=0)+(LEN(AR11)=0)+(LEN(AT11)=0)+(LEN(AU11)=0)+(LEN(AV11)=0)+(LEN(AX11)=0)) | BB11: =IF($B11="","",IF(AND(BA11=0,AZ11>=1),"Complete","Incomplete"))
A12: arkaroola-au | B12: Arkaroola | C12: Arkaroola Wilderness Sanctuary; Arkaroola Protection Area; Mount Painter Inlier | D12: Australia | E12: AU | F12: Northern Flinders Ranges, South Australia | G12: -30.312 | H12: 139.336 | I12: Approximately 10 km | J12: No | K12: 610 | L12: A 610 km² wilderness sanctuary in the northern Flinders Ranges, chosen by Mars Society Australia as its main Mars analogue research area. It has Neoproterozoic sediments and stromatolites, fossil hydrothermal systems (Mount Gee) and radioactive hot springs nearby (Paralana). | M12: Mars | O12: Mineralogical | P12: Geological / geomorphological; Habitability / biological; Operational (instrument, rover or crew testing) | Q12: Fossil hydrothermal alteration and quartz-breccia systems in the Mount Painter Inlier (Mount Gee). Paralana radioactive hot springs with algal mats. Neoproterozoic stromatolites and ripple-laminated sandstones. | R12: Thomas & Walter (2002) used airborne and field short-wave infrared hyperspectral data to map hydrothermal alteration in the Mount Painter Inlier, as a test for characterising putative hydrothermal deposits on Mars. Mars Society Australia uses the area's varied rocks, regolith and duricrusts for remote-sensing, instrument and simulated-base testing. | T12: Hydrothermal / ore deposit | U12: Mesoproterozoic basement and uranium-bearing granite; quartz–hematite breccias; Wooltana Basalt; Neoproterozoic evaporitic, carbonate and clastic sediments (Callanna and Burra Groups); Sturtian tillites; stromatolites; iron, silica, carbonate and sulphate duricrusts | V12: Kaolinite; Muscovite; Biotite; K Feldspar; Halloysite; Quartz; Hematite | W12: Mesoproterozoic basement. Neoproterozoic sediments, including a stromatolite about 650 million years old. The main hydrothermal alteration is tentatively Permo-Carboniferous. Paralana springs are active today. | X12: Hot spring / hydrothermal | AC12: 80 | AF12: 640 | AG12: Yes | AH12: Algal mats on the floor of the Paralana hot springs in a high-radioactivity setting | AI12: 2 | AL12: Private | AO12: About 600–700 km north of Adelaide, roughly 8 hours by road. Charter flights are available from Adelaide airfields. The sanctuary offers guided 4WD tours (e.g. the Ridgetop tour) as well as self-drive tracks and bushwalking. | AQ12: 2 | AR12: Toxic gas | AS12: Radon (heavier than air) is emitted at the Paralana hot springs, so prolonged stays near the springs may be a health hazard. | AV12: 46306 | AX12: Draft | AY12: Ratings are PROPOSALS by Claude: check against Rating scales, then fill rating_last_reviewed. geological_setting also: Sedimentary basin land_status also: Protected area / national park Open issues: see Research log tab. | AZ12: =IF($B12="","",COUNTIF(References!$A$4:$A$503,$A12)) | BA12: =IF($B12="","",(LEN(A12)=0)+(LEN(B12)=0)+(LEN(D12)=0)+(LEN(G12)=0)+(LEN(H12)=0)+(LEN(I12)=0)+(LEN(J12)=0)+(LEN(L12)=0)+(LEN(M12)=0)+(LEN(O12)=0)+(LEN(R12)=0)+(LEN(X12)=0)+(LEN(AI12)=0)+(LEN(AJ12)=0)+(LEN(AQ12)=0)+(LEN(AR12)=0)+(LEN(AT12)=0)+(LEN(AU12)=0)+(LEN(AV12)=0)+(LEN(AX12)=0)) | BB12: =IF($B12="","",IF(AND(BA12=0,AZ12>=1),"Complete","Incomplete"))
A13: lanzarote-es | B13: Lanzarote | C13: Lanzarote and Chinijo Islands UNESCO Global Geopark; Timanfaya National Park | D13: Spain | E13: ES | F13: Canary Islands | G13: 29.039 | H13: -13.638 | I13: Region only | J13: No | K13: 886.85 | L13: Volcanic island in the Canary Islands with young lava fields (Timanfaya eruptions of 1730–1736 and 1824) and lava tubes. A Mars and Moon analogue used by ESA for PANGAEA astronaut geology training and for lava-tube astrobiology studies. | M13: Mars | N13: Moon | O13: Volcanic | P13: Operational (instrument, rover or crew testing); Habitability / biological | Q13: Martian and lunar volcanic terrains and lava tubes; interaction of volcanic activity and water | R13: Lanzarote has been described as one of the best terrestrial analogues for Martian volcanology, and its barren volcanic landscape is used by ESA to train astronauts in planetary field geology. Its lava tubes host secondary minerals and microbial communities whose biosignatures (e.g. Ca-rich fluorapatite precipitates) inform life-detection strategies for Martian caves. | T13: Volcanic | V13: Calcite; Fluorapatite; Gypsum; Halite; Opal | W13: Geological processes active for more than 15 Ma; historical eruptions 1730–1736 and 1824 (Timanfaya) | X13: Lava field / lava tube | Y13: Cave; Hot spring / hydrothermal | AF13: 671 | AG13: Yes | AH13: Crossiella; halophilic and halotolerant chemoorganotrophic bacteria (lava tubes); Salinisphaera; Alcanivorax; Alicyclobacillus (La Corona lava tube); lichens (Timanfaya) | AI13: 2 | AJ13: Varies | AK13: Timanfaya National Park direction (Parques Nacionales de Canarias); Lanzarote and Chinijo Islands UNESCO Global Geopark / Cabildo de Lanzarote | AL13: Protected area / national park | AM13: Arrecife; Yaiza; Tinajo | AO13: Timanfaya is reached by road (LZ-67 from Yaiza or Tinajo). Private vehicles may drive to Islote de Hilario (fee at the Taro gate); the Ruta de los Volcanes is only by Cabildo bus; guided walks (e.g. Termesana) must be booked in advance at the Mancha Blanca Visitor Centre. | AP13: In Timanfaya it is not permitted to walk or drive outside areas set up for public use (fragile lichens); plant collecting is prohibited; free independent access only on the coastal path; the Restricted Use Zone needs prior authorisation from the park direction; the Reserve Zone (over 90% of the park) is open only for scientific or management purposes. | AQ13: 2 | AR13: Extreme heat | AS13: Timanfaya has geothermal anomalies with surface temperatures above 100 °C; about 277 °C has been recorded at 10 cm depth at Islote de Hilario. Keep to designated areas. | AV13: 46306 | AX13: Draft | AY13: Ratings are PROPOSALS by Claude: check against Rating scales, then fill rating_last_reviewed. land_status also: UNESCO site Open issues: see Research log tab. | AZ13: =IF($B13="","",COUNTIF(References!$A$4:$A$503,$A13)) | BA13: =IF($B13="","",(LEN(A13)=0)+(LEN(B13)=0)+(LEN(D13)=0)+(LEN(G13)=0)+(LEN(H13)=0)+(LEN(I13)=0)+(LEN(J13)=0)+(LEN(L13)=0)+(LEN(M13)=0)+(LEN(O13)=0)+(LEN(R13)=0)+(LEN(X13)=0)+(LEN(AI13)=0)+(LEN(AJ13)=0)+(LEN(AQ13)=0)+(LEN(AR13)=0)+(LEN(AT13)=0)+(LEN(AU13)=0)+(LEN(AV13)=0)+(LEN(AX13)=0)) | BB13: =IF($B13="","",IF(AND(BA13=0,AZ13>=1),"Complete","Incomplete"))
A14: bockfjord-svalbard-sj | B14: Bockfjord Volcanic Complex | C14: Bockfjorden Volcanic Complex; Sverrefjell (Sverrefjellet); Sigurdfjell | D14: Norway (Svalbard) | E14: SJ | F14: Bockfjorden, Haakon VII Land, Spitsbergen, Svalbard | G14: 79.432 | H14: 13.305 | I14: Approximately 10 km | J14: Yes | L14: Quaternary basaltic volcanoes (Sverrefjell, Sigurdfjell) beside Bockfjorden, Svalbard. They contain carbonate globules like those in Martian meteorite ALH84001, with warm springs nearby. A long-running AMASE site for testing Mars instruments and astrobiology methods. | M14: Mars | O14: Mineralogical | P14: Geochemical; Volcanic; Habitability / biological; Operational (instrument, rover or crew testing) | Q14: Dolomite–magnesite carbonate globules in mantle xenoliths and lava vesicles; vent-hosted magnesite and carbonate-cemented lava breccias; Jotun and Troll warm springs | R14: Carbonate globules at Sverrefjell show carbonate and iron-oxide zoning similar to those in ALH84001, so they help test low-temperature hydrothermal and abiotic carbon-synthesis models for the meteorite. Breccia cements at Sverrefjell are an analogue for the Comanche carbonates at Gusev crater. AMASE has used the complex to test MSL and ExoMars instruments and contamination protocols. | T14: Volcanic | U14: Basalt; peridotite (mantle xenoliths); carbonate-cemented lava breccia | V14: Calcite; Dolomite; Magnesite; Huntite; Aragonite; Magnetite; Olivine; Allophane | W14: Sverrefjell and Sigurdfjell formed in subglacial eruptions c. 1 Ma (Amundsen et al. 2011). Wikipedia gives Sverrefjellet's formation as c. 2.6 Ma, with a last eruption between 6 ka and 1 Ma. | X14: Hot spring / hydrothermal | Y14: Glacial / subglacial | AC14: 25.6 | AF14: 507 | AI14: 4 | AJ14: Yes | AK14: Governor of Svalbard (Sysselmesteren) | AL14: Protected area / national park | AN14: Summer (AMASE fieldwork has been in August) | AP14: Register every project and fieldwork location in the Research in Svalbard (RiS) database. Apply by the fixed deadlines (15 Jan, 1 Mar, 1 Jul, 1 Oct); processing takes up to 8 weeks, and fieldwork must not start before the Governor replies. Fieldwork in national parks usually needs an exemption from the Governor. Loose stones need no permit in principle, but the area's protection rules still apply. Fossil collecting in protected areas needs an application. Terrain interventions larger than 20 × 20 cm need permission. Pre-1946 cultural monuments are protected, with a 100 m zone. Work under the Svalbard Environmental Protection Act. | AQ14: 4 | AR14: Dangerous wildlife | AS14: Polar bears: anyone outside settlements must carry suitable means of scaring off polar bears, and the Governor recommends a firearm. Campsites must be secured against bears, and camps that need an application must keep an awake, organised bear guard whenever people are present. Anyone travelling outside Management Area 10 must carry an emergency beacon registered with the Governor. Satellite phones cannot dial 112. | AV14: 46306 | AX14: Draft | AY14: Ratings are PROPOSALS by Claude: check against Rating scales, then fill rating_last_reviewed. Open issues: see Research log tab. | AZ14: =IF($B14="","",COUNTIF(References!$A$4:$A$503,$A14)) | BA14: =IF($B14="","",(LEN(A14)=0)+(LEN(B14)=0)+(LEN(D14)=0)+(LEN(G14)=0)+(LEN(H14)=0)+(LEN(I14)=0)+(LEN(J14)=0)+(LEN(L14)=0)+(LEN(M14)=0)+(LEN(O14)=0)+(LEN(R14)=0)+(LEN(X14)=0)+(LEN(AI14)=0)+(LEN(AJ14)=0)+(LEN(AQ14)=0)+(LEN(AR14)=0)+(LEN(AT14)=0)+(LEN(AU14)=0)+(LEN(AV14)=0)+(LEN(AX14)=0)) | BB14: =IF($B14="","",IF(AND(BA14=0,AZ14>=1),"Complete","Incomplete"))
A15: mauna-kea-us | B15: Mauna Kea | C15: Maunakea; Puʻu Hiwahine (2010 ISRU test site) | D15: United States | E15: US | F15: Hawaiʻi Island, Hawaii | G15: 19.821 | H15: -155.468 | I15: Approximately 10 km | J15: Yes | L15: Dormant shield volcano on Hawaiʻi Island whose fine-grained volcanic slopes hosted the 2010 and 2012 ILSO-ISRU field tests (PISCES, NASA, CSA, DLR, NORCAT) as a lunar and Mars analogue for instruments and resource extraction. | M15: Moon | N15: Mars | O15: Operational (instrument, rover or crew testing) | P15: Volcanic; Mineralogical | Q15: Fine-grained volcanic material and cinder-cone slopes (e.g. Puʻu Hiwahine, c. 2800 m) used for excavation, site preparation, mobility and ISRU instrument tests | R15: Mauna Kea hosted the 2010 ILSO-ISRU campaign, in which eight science teams tested and calibrated lunar in-situ instruments, and a 2012 follow-up under PISCES. Its fine-grained volcanic material is described as a suitable lunar and Martian analogue, and the site was proposed as a standard calibration location. | S15: An atmosphere, water and weathering make the material and conditions unlike the airless lunar surface; access and activities are limited by cultural, environmental and astronomical constraints. | T15: Volcanic | U15: Tholeiitic basalt; alkali basalt; hawaiite; mugearite; volcanic glass; gabbro | W15: Volcano c. 1 million years old; oldest dated rock c. 237,000 years (±31,000) | X15: High altitude / high UV | Y15: Lava field / lava tube | AE15: 2800 | AF15: 4207 | AI15: 3 | AK15: University of Hawaiʻi at Hilo Center for Maunakea Stewardship (formerly Office of Maunakea Management); Maunakea Stewardship and Oversight Authority (taking over management, transition from 1 July 2023) | AL15: Research station | AM15: Hilo | AO15: Saddle Road crosses the plateau between Mauna Kea and Mauna Loa. The summit road climbs nearly 5,000 ft over eight miles from the Visitor Information Station (2,804 m); it is unpaved, steep and requires dependable 4WD with low range above the VIS. No public fuel; arrive with at least half a tank. Summit open from 30 min before sunrise to 30 min after sunset. | AP15: Do not move, remove, collect or leave anything, including rocks. Rock piles may be cultural altars or markers protected by law. Stay on marked trails and roads; no off-road driving. Vehicles must be clean and free of invasive species. | AQ15: 4 | AR15: Altitude; Extreme cold; Remoteness / no phone signal | AS15: Acclimatise at least 30 minutes at the VIS (2,804 m) before going higher; descend immediately with altitude-illness symptoms. Children under 13, pregnant people, anyone who dived in the previous 24 hours or has heart, lung or blood-pressure conditions should not go above the VIS. Drink c. 500 ml per hour. Winter storms bring freezing temperatures, winds over 100 mph and white-outs. Intense UV. Mobile phones are for emergencies only; help may be hours away. | AV15: 46306 | AX15: Draft | AY15: Ratings are PROPOSALS by Claude: check against Rating scales, then fill rating_last_reviewed. Open issues: see Research log tab. | AZ15: =IF($B15="","",COUNTIF(References!$A$4:$A$503,$A15)) | BA15: =IF($B15="","",(LEN(A15)=0)+(LEN(B15)=0)+(LEN(D15)=0)+(LEN(G15)=0)+(LEN(H15)=0)+(LEN(I15)=0)+(LEN(J15)=0)+(LEN(L15)=0)+(LEN(M15)=0)+(LEN(O15)=0)+(LEN(R15)=0)+(LEN(X15)=0)+(LEN(AI15)=0)+(LEN(AJ15)=0)+(LEN(AQ15)=0)+(LEN(AR15)=0)+(LEN(AT15)=0)+(LEN(AU15)=0)+(LEN(AV15)=0)+(LEN(AX15)=0)) | BB15: =IF($B15="","",IF(AND(BA15=0,AZ15>=1),"Complete","Incomplete"))
A16: boulby-mine-gb | B16: Boulby Mine | C16: Boulby Underground Laboratory; Palmer Lab | D16: United Kingdom | E16: GB | F16: North Yorkshire, England | G16: 54.553 | H16: -0.825 | I16: Approximately 10 km | J16: No | L16: Working potash and polyhalite mine on the North Yorkshire coast hosting the STFC Boulby Underground Laboratory 1.1 km below ground in ~250-million-year-old Zechstein evaporites. Used for Mars-analogue instrument testing (MINAR) and deep subsurface brine habitability studies. | M16: Mars | O16: Operational (instrument, rover or crew testing) | P16: Habitability / biological; Mineralogical | Q16: Martian subsurface evaporites and brines | R16: The MINAR programme used Boulby's Permian evaporite sequence to test a planetary instrument suite (camera emulators, Raman, handheld XRD, drills) for characterising geological context and mineralogy at millimetre to metre scales. Subsurface brines in the mine show how ionic strength and water activity limit life, relevant to potentially habitable Martian brines. | S16: Active commercial mine with engineered roadways, air conditioning and human contamination; brines examined were not extreme in ionic strength. | T16: Evaporite basin | U16: Rock salt (halite); potash (sylvinite); polyhalite; dolomite; anhydrite; shale | V16: Halite; Sylvite; Polyhalite; Carnallite; Anhydrite; Dolomite | W16: Permian (Zechstein Sea evaporites, about 250 Ma) | X16: Evaporite | Y16: Hypersaline | Z16: 3.42 | AA16: 7.25 | AB16: 29.5 | AC16: 35.7 | AD16: Brine ionic strength 5.32–6.56 mol/L; Cl⁻ 159,347–209,639 mg/L; water activity 0.566–0.742 | AG16: Yes | AH16: Halobacteriales archaea (Haloarcula, Natronomonas, Halogeometricum, Halomicrobium, Halobacterium); Proteobacteria; Bacteroidetes; Firmicutes | AI16: 5 | AJ16: Yes | AK16: STFC Boulby Underground Laboratory (with ICL-UK, mine operator) | AL16: Research station | AM16: Loftus | AO16: Surface facilities lie just south-east of Boulby village, about 4.3 km east of Loftus, between Saltburn and Whitby. The laboratory is about 1,100 m underground in an operating mine. | AP16: Access only by arrangement with the Boulby Underground Laboratory (contact the lab to discuss facility access); no public access. | AQ16: 3 | AV16: 46306 | AX16: Draft | AY16: Ratings are PROPOSALS by Claude: check against Rating scales, then fill rating_last_reviewed. Open issues: see Research log tab. | AZ16: =IF($B16="","",COUNTIF(References!$A$4:$A$503,$A16)) | BA16: =IF($B16="","",(LEN(A16)=0)+(LEN(B16)=0)+(LEN(D16)=0)+(LEN(G16)=0)+(LEN(H16)=0)+(LEN(I16)=0)+(LEN(J16)=0)+(LEN(L16)=0)+(LEN(M16)=0)+(LEN(O16)=0)+(LEN(R16)=0)+(LEN(X16)=0)+(LEN(AI16)=0)+(LEN(AJ16)=0)+(LEN(AQ16)=0)+(LEN(AR16)=0)+(LEN(AT16)=0)+(LEN(AU16)=0)+(LEN(AV16)=0)+(LEN(AX16)=0)) | BB16: =IF($B16="","",IF(AND(BA16=0,AZ16>=1),"Complete","Incomplete"))
